Workbook

Sheet Main
A1: Func type | H1: Out Type | T1: speed | AC1: Pull UP/DWN
A2: 00 | B2: Input (reset state) | H2: 0 | I2: Output push-pull (reset state) | T2: 00 | U2: low speed 2MHz | AC2: 00 | AD2: No pull-up, pull-down
A3: 01 | B3: General purpose output mode | H3: 1 | I3: Output open-drain | T3: 01 | U3: Medium Speed 10 MHz | AC3: 01 | AD3: Pull-up
A4: 10 | B4: Alternate function mode | T4: 10 | U4: Low Speed | AC4: 10 | AD4: Pull-down
A5: 11 | B5: Analog mode | T5: 11 | U5: High Speed 50 Mhz | AC5: 11 | AD5: Reserved
B7: Pin15 | D7: Pin14 | F7: Pin13 | H7: Pin12 | J7: Pin11 | L7: Pin10 | N7: Pin9 | P7: Pin8 | R7: Pin7 | T7: Pin6 | V7: Pin5 | X7: Pin4 | Z7: Pin3 | AB7: Pin2 | AD7: Pin1 | AF7: Pin0
A9: Port A
A10: Pin No | B10: 50 | D10: 49 | F10: 46 | H10: 45 | J10: 44 | L10: 43 | N10: 42 | P10: 41 | R10: 23 | T10: 22 | V10: 21 | X10: 20 | Z10: 18 | AB10: 16 | AD10: 15 | AF10: 14
A11: Funct | B11: R_EN | D11: SWCLK/JTCK | F11: SWDIO/JTMS | H11: LED5 | J11: LED4 | L11: LED3 | N11: LED2 | P11: LED1 | R11: NA | T11: NA | V11: NA | X11: NA | Z11: RCLK | AB11: OE | AD11: SCK | AF11: MOSI
A12: Fun TYPE | B12: 0 | C12: 1 | D12: 1 | E12: 0 | F12: 1 | G12: 0 | H12: 0 | I12: 1 | J12: 0 | K12: 1 | L12: 0 | M12: 1 | N12: 0 | O12: 1 | P12: 0 | Q12: 1 | R12: 0 | S12: 1 | T12: 0 | U12: 1 | V12: 0 | W12: 1 | X12: 0 | Y12: 1 | Z12: 0 | AA12: 1 | AB12: 0 | AC12: 1 | AD12: 0 | AE12: 1 | AF12: 0 | AG12: 1 | AH12: GPIOA->MODER | AI12: =com.sun.star.sheet.addin.Analysis.getDec2Hex(AH19) -> 69555555
A13: OUT TYPE | B13: 0 | D13: 0 | F13: 0 | H13: 0 | J13: 0 | L13: 0 | N13: 0 | P13: 0 | R13: 0 | T13: 0 | V13: 0 | X13: 0 | Z13: 0 | AB13: 0 | AD13: 0 | AF13: 0 | AH13: GPIOA->OTYPER | AI13: =com.sun.star.sheet.addin.Analysis.getDec2Hex(AH20) -> 0 | AJ13: PUSH PULL
A14: SPEED | B14: 0 | C14: 0 | D14: 1 | E14: 1 | F14: 1 | G14: 1 | H14: 0 | I14: 0 | J14: 0 | K14: 0 | L14: 0 | M14: 0 | N14: 0 | O14: 0 | P14: 0 | Q14: 0 | R14: 0 | S14: 0 | T14: 0 | U14: 0 | V14: 0 | W14: 0 | X14: 0 | Y14: 0 | Z14: 0 | AA14: 0 | AB14: 0 | AC14: 0 | AD14: 0 | AE14: 0 | AF14: 0 | AG14: 0 | AH14: GPIOA->OSPEEDR | AI14: =com.sun.star.sheet.addin.Analysis.getDec2Hex(AH21) -> 3C000000 | AJ14: Medium Speed 2 Mhz
A15: Pull Up/Dn | B15: 0 | C15: 0 | D15: 1 | E15: 0 | F15: 0 | G15: 1 | H15: 0 | I15: 0 | J15: 0 | K15: 0 | L15: 0 | M15: 0 | N15: 0 | O15: 0 | P15: 0 | Q15: 0 | R15: 0 | S15: 0 | T15: 0 | U15: 0 | V15: 0 | W15: 0 | X15: 0 | Y15: 0 | Z15: 0 | AA15: 0 | AB15: 0 | AC15: 1 | AD15: 0 | AE15: 0 | AF15: 0 | AG15: 0 | AH15: GPIOA->PUPDR | AI15: =com.sun.star.sheet.addin.Analysis.getDec2Hex(AH22) -> 24000010 | AJ15: Pull Up/Down
A16: ALT FUNCT | B16: 0 | C16: 0 | D16: 0 | E16: 0 | F16: 0 | G16: 0 | H16: 0 | I16: 0 | J16: 0 | K16: 0 | L16: 0 | M16: 0 | N16: 0 | O16: 0 | P16: 0 | Q16: 0 | R16: 0 | S16: 0 | T16: 0 | U16: 0 | V16: 0 | W16: 0 | X16: 0 | Y16: 0 | Z16: 0 | AA16: 0 | AB16: 0 | AC16: 0 | AD16: 0 | AE16: 0 | AF16: 0 | AG16: 0 | AH16: GPIOB->AFR[0] | AI16: =com.sun.star.sheet.addin.Analysis.getDec2Hex(AH23) -> 0
B17: 0 | C17: 0 | D17: 0 | E17: 0 | F17: 0 | G17: 0 | H17: 0 | I17: 0 | J17: 0 | K17: 0 | L17: 0 | M17: 0 | N17: 0 | O17: 0 | P17: 0 | Q17: 0 | R17: 0 | S17: 0 | T17: 0 | U17: 0 | V17: 0 | W17: 0 | X17: 0 | Y17: 0 | Z17: 0 | AA17: 0 | AB17: 0 | AC17: 0 | AD17: 0 | AE17: 0 | AF17: 0 | AG17: 0 | AH17: GPIOA->AFR[1] | AI17: =com.sun.star.sheet.addin.Analysis.getDec2Hex(AH24) -> 0
B18: 31 | C18: 30 | D18: 29 | E18: 28 | F18: 27 | G18: 26 | H18: 25 | I18: 24 | J18: 23 | K18: 22 | L18: 21 | M18: 20 | N18: 19 | O18: 18 | P18: 17 | Q18: 16 | R18: 15 | S18: 14 | T18: 13 | U18: 12 | V18: 11 | W18: 10 | X18: 9 | Y18: 8 | Z18: 7 | AA18: 6 | AB18: 5 | AC18: 4 | AD18: 3 | AE18: 2 | AF18: 1 | AG18: 0
A19: Fun TYPE | B19: =IF(B12>0,2^B$18,0) -> 0 | C19: =IF(C12>0,2^C$18,0) -> 1073741824 | D19: =IF(D12>0,2^D$18,0) -> 536870912 | E19: =IF(E12>0,2^E$18,0) -> 0 | F19: =IF(F12>0,2^F$18,0) -> 134217728 | G19: =IF(G12>0,2^G$18,0) -> 0 | H19: =IF(H12>0,2^H$18,0) -> 0 | I19: =IF(I12>0,2^I$18,0) -> 16777216 | ... AG19: =IF(AG12>0,2^AG$18,0) -> 1 | AH19: =SUM(B19:AG19) -> 1767200085
A20: OUT TYPE | R20: =IF(B13>0,2^R$18,0) -> 0 | S20: =IF(D13>0,2^S$18,0) -> 0 | T20: =IF(F13>0,2^T$18,0) -> 0 | U20: =IF(H13>0,2^U$18,0) -> 0 | V20: =IF(J13>0,2^V$18,0) -> 0 | W20: =IF(L13>0,2^W$18,0) -> 0 | X20: =IF(N13>0,2^X$18,0) -> 0 | Y20: =IF(P13>0,2^Y$18,0) -> 0 | Z20: =IF(R13>0,2^Z$18,0) -> 0 | AA20: =IF(T13>0,2^AA$18,0) -> 0 | AB20: =IF(V13>0,2^AB$18,0) -> 0 | AC20: =IF(X13>0,2^AC$18,0) -> 0 | AD20: =IF(Z13>0,2^AD$18,0) -> 0 | AE20: =IF(AB13>0,2^AE$18,0) -> 0 | AF20: =IF(AD13>0,2^AF$18,0) -> 0 | AG20: =IF(AF13>0,2^AG$18,0) -> 0 | AH20: =SUM(R20:AG20) -> 0
A21: Speed | B21: =IF(B14>0,2^B$18,0) -> 0 | C21: =IF(C14>0,2^C$18,0) -> 0 | D21: =IF(D14>0,2^D$18,0) -> 536870912 | E21: =IF(E14>0,2^E$18,0) -> 268435456 | F21: =IF(F14>0,2^F$18,0) -> 134217728 | G21: =IF(G14>0,2^G$18,0) -> 67108864 | H21: =IF(H14>0,2^H$18,0) -> 0 | I21: =IF(I14>0,2^I$18,0) -> 0 | ... AG21: =IF(AG14>0,2^AG$18,0) -> 0 | AH21: =SUM(B21:AG21) -> 1006632960
A22: Pull Up/Dn | B22: =IF(B15>0,2^B$18,0) -> 0 | C22: =IF(C15>0,2^C$18,0) -> 0 | D22: =IF(D15>0,2^D$18,0) -> 536870912 | E22: =IF(E15>0,2^E$18,0) -> 0 | F22: =IF(F15>0,2^F$18,0) -> 0 | G22: =IF(G15>0,2^G$18,0) -> 67108864 | H22: =IF(H15>0,2^H$18,0) -> 0 | I22: =IF(I15>0,2^I$18,0) -> 0 | ... AG22: =IF(AG15>0,2^AG$18,0) -> 0 | AH22: =SUM(B22:AG22) -> 603979792
A23: ALT FUNCT[0] | B23: =IF(B16>0,2^B$18,0) -> 0 | C23: =IF(C16>0,2^C$18,0) -> 0 | D23: =IF(D16>0,2^D$18,0) -> 0 | E23: =IF(E16>0,2^E$18,0) -> 0 | F23: =IF(F16>0,2^F$18,0) -> 0 | G23: =IF(G16>0,2^G$18,0) -> 0 | H23: =IF(H16>0,2^H$18,0) -> 0 | I23: =IF(I16>0,2^I$18,0) -> 0 | ... AG23: =IF(AG16>0,2^AG$18,0) -> 0 | AH23: =SUM(B23:AG23) -> 0
A24: ALT FUNCT[1] | B24: =IF(B17>0,2^B$18,0) -> 0 | C24: =IF(C17>0,2^C$18,0) -> 0 | D24: =IF(D17>0,2^D$18,0) -> 0 | E24: =IF(E17>0,2^E$18,0) -> 0 | F24: =IF(F17>0,2^F$18,0) -> 0 | G24: =IF(G17>0,2^G$18,0) -> 0 | H24: =IF(H17>0,2^H$18,0) -> 0 | I24: =IF(I17>0,2^I$18,0) -> 0 | ... AG24: =IF(AG17>0,2^AG$18,0) -> 0 | AH24: =SUM(B24:AG24) -> 0
A28: Port B
A29: Pin No | B29: 35 | D29: 34 | F29: NC | H29: NC | J29: NC | L29: NC | N29: 62 | P29: 61 | R29: 59 | T29: 58 | V29: 57 | X29: 56 | Z29: 55 | AB29: 28 | AD29: 27 | AF29: 26
A30: Funct | B30: SDADC3_8M | D30: SDADC3_8P | F30: NC | H30: NC | J30: NC | L30: NC | N30: DB7 | P30: DB6 | R30: DB5 | T30: DB4 | V30: DB3 | X30: SW3 | Z30: SW2 | AB30: SW1 | AD30: SDADC1_6M | AF30: SDADC1_6P
A31: Fun TYPE | B31: 1 | C31: 1 | D31: 1 | E31: 1 | F31: 0 | G31: 0 | H31: 0 | I31: 0 | J31: 0 | K31: 0 | L31: 0 | M31: 0 | N31: 0 | O31: 1 | P31: 0 | Q31: 1 | R31: 0 | S31: 1 | T31: 0 | U31: 1 | V31: 0 | W31: 1 | X31: 0 | Y31: 0 | Z31: 0 | AA31: 0 | AB31: 0 | AC31: 0 | AD31: 1 | AE31: 1 | AF31: 1 | AG31: 1 | AH31: GPIOB->MODER | AI31: =com.sun.star.sheet.addin.Analysis.getDec2Hex(AH38) -> F005540F
A32: OUT TYPE | B32: 0 | D32: 0 | F32: 0 | H32: 0 | J32: 0 | L32: 0 | N32: 0 | P32: 0 | R32: 0 | T32: 0 | V32: 0 | X32: 0 | Z32: 0 | AB32: 0 | AD32: 0 | AF32: 0 | AH32: GPIOB->OTYPER | AI32: =com.sun.star.sheet.addin.Analysis.getDec2Hex(AH39) -> 0 | AJ32: PUSH PULL
A33: SPEED | B33: 0 | C33: 0 | D33: 0 | E33: 0 | F33: 0 | G33: 0 | H33: 0 | I33: 0 | J33: 0 | K33: 0 | L33: 0 | M33: 0 | N33: 0 | O33: 0 | P33: 0 | Q33: 0 | R33: 0 | S33: 0 | T33: 0 | U33: 0 | V33: 0 | W33: 0 | X33: 0 | Y33: 0 | Z33: 0 | AA33: 0 | AB33: 0 | AC33: 0 | AD33: 0 | AE33: 0 | AF33: 0 | AG33: 0 | AH33: GPIOB->OSPEEDR | AI33: =com.sun.star.sheet.addin.Analysis.getDec2Hex(AH40) -> 0 | AJ33: Medium Speed 2 Mhz
A34: Pull Up/Dn | B34: 0 | C34: 0 | D34: 0 | E34: 0 | F34: 0 | G34: 0 | H34: 0 | I34: 0 | J34: 0 | K34: 0 | L34: 0 | M34: 0 | N34: 0 | O34: 0 | P34: 0 | Q34: 0 | R34: 0 | S34: 0 | T34: 0 | U34: 0 | V34: 0 | W34: 0 | X34: 0 | Y34: 1 | Z34: 0 | AA34: 1 | AB34: 0 | AC34: 1 | AD34: 0 | AE34: 0 | AF34: 0 | AG34: 0 | AH34: GPIOB->PUPDR | AI34: =com.sun.star.sheet.addin.Analysis.getDec2Hex(AH41) -> 150 | AJ34: Pull Up/Down
A35: ALT FUNCT | B35: 0 | C35: 0 | D35: 0 | E35: 0 | F35: 0 | G35: 0 | H35: 0 | I35: 0 | J35: 0 | K35: 0 | L35: 0 | M35: 0 | N35: 0 | O35: 0 | P35: 0 | Q35: 0 | R35: 0 | S35: 0 | T35: 0 | U35: 0 | V35: 0 | W35: 0 | X35: 0 | Y35: 0 | Z35: 0 | AA35: 0 | AB35: 0 | AC35: 0 | AD35: 0 | AE35: 0 | AF35: 0 | AG35: 0 | AH35: GPIOB->AFR[0] | AI35: =com.sun.star.sheet.addin.Analysis.getDec2Hex(AH42) -> 0
B36: 0 | C36: 0 | D36: 0 | E36: 0 | F36: 0 | G36: 0 | H36: 0 | I36: 0 | J36: 0 | K36: 0 | L36: 0 | M36: 0 | N36: 0 | O36: 0 | P36: 0 | Q36: 0 | R36: 0 | S36: 0 | T36: 0 | U36: 0 | V36: 0 | W36: 0 | X36: 0 | Y36: 0 | Z36: 0 | AA36: 0 | AB36: 0 | AC36: 0 | AD36: 0 | AE36: 0 | AF36: 0 | AG36: 0 | AH36: GPIOB->AFR[1] | AI36: =com.sun.star.sheet.addin.Analysis.getDec2Hex(AH43) -> 0
B37: 31 | C37: 30 | D37: 29 | E37: 28 | F37: 27 | G37: 26 | H37: 25 | I37: 24 | J37: 23 | K37: 22 | L37: 21 | M37: 20 | N37: 19 | O37: 18 | P37: 17 | Q37: 16 | R37: 15 | S37: 14 | T37: 13 | U37: 12 | V37: 11 | W37: 10 | X37: 9 | Y37: 8 | Z37: 7 | AA37: 6 | AB37: 5 | AC37: 4 | AD37: 3 | AE37: 2 | AF37: 1 | AG37: 0
A38: Fun TYPE | B38: =IF(B31>0,2^B$18,0) -> 2147483648 | C38: =IF(C31>0,2^C$18,0) -> 1073741824 | D38: =IF(D31>0,2^D$18,0) -> 536870912 | E38: =IF(E31>0,2^E$18,0) -> 268435456 | F38: =IF(F31>0,2^F$18,0) -> 0 | G38: =IF(G31>0,2^G$18,0) -> 0 | H38: =IF(H31>0,2^H$18,0) -> 0 | I38: =IF(I31>0,2^I$18,0) -> 0 | ... AG38: =IF(AG31>0,2^AG$18,0) -> 1 | AH38: =SUM(B38:AG38) -> 4026881039
A39: OUT TYPE | R39: =IF(B32>0,2^R$18,0) -> 0 | S39: =IF(D32>0,2^S$18,0) -> 0 | T39: =IF(F32>0,2^T$18,0) -> 0 | U39: =IF(H32>0,2^U$18,0) -> 0 | V39: =IF(J32>0,2^V$18,0) -> 0 | W39: =IF(L32>0,2^W$18,0) -> 0 | X39: =IF(N32>0,2^X$18,0) -> 0 | Y39: =IF(P32>0,2^Y$18,0) -> 0 | Z39: =IF(R32>0,2^Z$18,0) -> 0 | AA39: =IF(T32>0,2^AA$18,0) -> 0 | AB39: =IF(V32>0,2^AB$18,0) -> 0 | AC39: =IF(X32>0,2^AC$18,0) -> 0 | AD39: =IF(Z32>0,2^AD$18,0) -> 0 | AE39: =IF(AB32>0,2^AE$18,0) -> 0 | AF39: =IF(AD32>0,2^AF$18,0) -> 0 | AG39: =IF(AF32>0,2^AG$18,0) -> 0 | AH39: =SUM(R39:AG39) -> 0
A40: Speed | B40: =IF(B33>0,2^B$18,0) -> 0 | C40: =IF(C33>0,2^C$18,0) -> 0 | D40: =IF(D33>0,2^D$18,0) -> 0 | E40: =IF(E33>0,2^E$18,0) -> 0 | F40: =IF(F33>0,2^F$18,0) -> 0 | G40: =IF(G33>0,2^G$18,0) -> 0 | H40: =IF(H33>0,2^H$18,0) -> 0 | I40: =IF(I33>0,2^I$18,0) -> 0 | ... AG40: =IF(AG33>0,2^AG$18,0) -> 0 | AH40: =SUM(B40:AG40) -> 0
A41: Pull Up/Dn | B41: =IF(B34>0,2^B$18,0) -> 0 | C41: =IF(C34>0,2^C$18,0) -> 0 | D41: =IF(D34>0,2^D$18,0) -> 0 | E41: =IF(E34>0,2^E$18,0) -> 0 | F41: =IF(F34>0,2^F$18,0) -> 0 | G41: =IF(G34>0,2^G$18,0) -> 0 | H41: =IF(H34>0,2^H$18,0) -> 0 | I41: =IF(I34>0,2^I$18,0) -> 0 | ... AG41: =IF(AG34>0,2^AG$18,0) -> 0 | AH41: =SUM(B41:AG41) -> 336
A42: ALT FUNCT[0] | B42: =IF(B35>0,2^B$18,0) -> 0 | C42: =IF(C35>0,2^C$18,0) -> 0 | D42: =IF(D35>0,2^D$18,0) -> 0 | E42: =IF(E35>0,2^E$18,0) -> 0 | F42: =IF(F35>0,2^F$18,0) -> 0 | G42: =IF(G35>0,2^G$18,0) -> 0 | H42: =IF(H35>0,2^H$18,0) -> 0 | I42: =IF(I35>0,2^I$18,0) -> 0 | ... AG42: =IF(AG35>0,2^AG$18,0) -> 0 | AH42: =SUM(B42:AG42) -> 0
A43: ALT FUNCT[1] | B43: =IF(B36>0,2^B$18,0) -> 0 | C43: =IF(C36>0,2^C$18,0) -> 0 | D43: =IF(D36>0,2^D$18,0) -> 0 | E43: =IF(E36>0,2^E$18,0) -> 0 | F43: =IF(F36>0,2^F$18,0) -> 0 | G43: =IF(G36>0,2^G$18,0) -> 0 | H43: =IF(H36>0,2^H$18,0) -> 0 | I43: =IF(I36>0,2^I$18,0) -> 0 | ... AG43: =IF(AG36>0,2^AG$18,0) -> 0 | AH43: =SUM(B43:AG43) -> 0
A48: Port C
A49: Pin No | B49: 4 | D49: 3 | F49: 2 | H49: 53 | J49: 52 | L49: 51 | N49: 40 | P49: 39 | R49: 38 | T49: 37 | V49: 25 | X49: 24 | Z49: 11 | AB49: 10 | AD49: 9 | AF49: 8
...

Sheet Alt Func
A3: S per the tables starting from page 41 of data sheet

Sheet ADC Channel set
B1: 31 | C1: 30 | D1: 29 | E1: 28 | F1: 27 | G1: 26 | H1: 25 | I1: 24 | J1: 23 | K1: 22 | L1: 21 | M1: 20 | N1: 19 | O1: 18 | P1: 17 | Q1: 16 | R1: 15 | S1: 14 | T1: 13 | U1: 12 | V1: 11 | W1: 10 | X1: 9 | Y1: 8 | Z1: 7 | AA1: 6 | AB1: 5 | AC1: 4 | AD1: 3 | AE1: 2 | AF1: 1 | AG1: 0
A5: ADC_SQR3 | B5: 0 | C5: 0 | D5: 0 | E5: 1 | F5: 0 | G5: 1 | H5: 0 | I5: 0 | J5: 1 | K5: 0 | L5: 1 | M5: 1 | N5: 0 | O5: 1 | P5: 1 | Q5: 0 | R5: 0 | S5: 0 | T5: 1 | U5: 1 | V5: 0 | W5: 0 | X5: 0 | Y5: 1 | Z5: 0 | AA5: 1 | AB5: 1 | AC5: 0 | AD5: 1 | AE5: 0 | AF5: 1 | AG5: 0 | AH5: =com.sun.star.sheet.addin.Analysis.getDec2Hex(AH12) -> 14B6316A | AJ5: 1 to 6
A6: ADC_SQR2 | B6: 0 | C6: 0 | D6: 0 | E6: 1 | F6: 0 | G6: 1 | H6: 0 | I6: 0 | J6: 1 | K6: 0 | L6: 1 | M6: 1 | N6: 0 | O6: 1 | P6: 1 | Q6: 0 | R6: 0 | S6: 0 | T6: 1 | U6: 1 | V6: 0 | W6: 0 | X6: 0 | Y6: 1 | Z6: 0 | AA6: 1 | AB6: 1 | AC6: 0 | AD6: 1 | AE6: 0 | AF6: 1 | AG6: 0 | AH6: =com.sun.star.sheet.addin.Analysis.getDec2Hex(AH13) -> 14B6316A | AJ6: 7 to 12
A7: ADC_SQR1 | B7: 0 | C7: 0 | D7: 0 | E7: 0 | F7: 0 | G7: 0 | H7: 0 | I7: 0 | J7: 1 | K7: 1 | L7: 0 | M7: 0 | N7: 0 | O7: 0 | P7: 0 | Q7: 0 | R7: 0 | S7: 0 | T7: 0 | U7: 0 | V7: 0 | W7: 0 | X7: 0 | Y7: 0 | Z7: 0 | AA7: 0 | AB7: 0 | AC7: 0 | AD7: 1 | AE7: 1 | AF7: 0 | AG7: 1 | AH7: =com.sun.star.sheet.addin.Analysis.getDec2Hex(AH14) -> C0000D | AJ7: 13 to 16 | AK7: second Last is total channels-1
I8: Channel Length | AK8: Last is empty
I9: One less than samples
B10: 0 | C10: 0 | D10: =IF(D3>0,2^D$1,0) -> 0 | E10: =IF(E3>0,2^E$1,0) -> 0 | F10: =IF(F3>0,2^F$1,0) -> 0 | G10: =IF(G3>0,2^G$1,0) -> 0 | H10: =IF(H3>0,2^H$1,0) -> 0 | I10: =IF(I3>0,2^I$1,0) -> 0 | J10: =IF(J3>0,2^J$1,0) -> 0 | K10: =IF(K3>0,2^K$1,0) -> 0 | ... AG10: =IF(AG3>0,2^AG$1,0) -> 0 | AH10: =SUM(B10:AG10) -> 0
B11: 0 | C11: 0 | D11: =IF(D4>0,2^D$1,0) -> 0 | E11: =IF(E4>0,2^E$1,0) -> 0 | F11: =IF(F4>0,2^F$1,0) -> 0 | G11: =IF(G4>0,2^G$1,0) -> 0 | H11: =IF(H4>0,2^H$1,0) -> 0 | I11: =IF(I4>0,2^I$1,0) -> 0 | J11: =IF(J4>0,2^J$1,0) -> 0 | K11: =IF(K4>0,2^K$1,0) -> 0 | ... AG11: =IF(AG4>0,2^AG$1,0) -> 0 | AH11: =SUM(B11:AG11) -> 0
B12: 0 | C12: 0 | D12: =IF(D5>0,2^D$1,0) -> 0 | E12: =IF(E5>0,2^E$1,0) -> 268435456 | F12: =IF(F5>0,2^F$1,0) -> 0 | G12: =IF(G5>0,2^G$1,0) -> 67108864 | H12: =IF(H5>0,2^H$1,0) -> 0 | I12: =IF(I5>0,2^I$1,0) -> 0 | J12: =IF(J5>0,2^J$1,0) -> 8388608 | K12: =IF(K5>0,2^K$1,0) -> 0 | ... AG12: =IF(AG5>0,2^AG$1,0) -> 0 | AH12: =SUM(B12:AG12) -> 347484522
B13: 0 | C13: 0 | D13: =IF(D6>0,2^D$1,0) -> 0 | E13: =IF(E6>0,2^E$1,0) -> 268435456 | F13: =IF(F6>0,2^F$1,0) -> 0 | G13: =IF(G6>0,2^G$1,0) -> 67108864 | H13: =IF(H6>0,2^H$1,0) -> 0 | I13: =IF(I6>0,2^I$1,0) -> 0 | J13: =IF(J6>0,2^J$1,0) -> 8388608 | K13: =IF(K6>0,2^K$1,0) -> 0 | ... AG13: =IF(AG6>0,2^AG$1,0) -> 0 | AH13: =SUM(B13:AG13) -> 347484522
B14: 0 | C14: 0 | D14: =IF(D7>0,2^D$1,0) -> 0 | E14: =IF(E7>0,2^E$1,0) -> 0 | F14: =IF(F7>0,2^F$1,0) -> 0 | G14: =IF(G7>0,2^G$1,0) -> 0 | H14: =IF(H7>0,2^H$1,0) -> 0 | I14: =IF(I7>0,2^I$1,0) -> 0 | J14: =IF(J7>0,2^J$1,0) -> 8388608 | K14: =IF(K7>0,2^K$1,0) -> 4194304 | ... AG14: =IF(AG7>0,2^AG$1,0) -> 1 | AH14: =SUM(B14:AG14) -> 12582925
D15: 9 | G15: 8 | J15: 7 | M15: 6 | P15: 5 | S15: 4 | V15: 3 | Y15: 2 | AB15: 1 | AE15: 0
AJ16: Sampling Time
A17: ADC_SMPR1 | B17: 0 | C17: 0 | D17: 1 | E17: 1 | F17: 0 | G17: 1 | H17: 1 | I17: 0 | J17: 1 | K17: 1 | L17: 0 | M17: 1 | N17: 1 | O17: 0 | P17: 1 | Q17: 1 | R17: 0 | S17: 1 | T17: 1 | U17: 0 | V17: 1 | W17: 1 | X17: 0 | Y17: 1 | Z17: 1 | AA17: 0 | AB17: 1 | AC17: 1 | AD17: 0 | AE17: 1 | AF17: 1 | AG17: 0 | AH17: =com.sun.star.sheet.addin.Analysis.getDec2Hex(AH21) -> 36DB6DB6 | AJ17: Channel | AK17: 20-29
A18: ADC_SMPR2 | B18: 0 | C18: 0 | D18: 0 | E18: 1 | F18: 1 | G18: 0 | H18: 1 | I18: 1 | J18: 0 | K18: 1 | L18: 1 | M18: 0 | N18: 1 | O18: 1 | P18: 0 | Q18: 1 | R18: 1 | S18: 0 | T18: 1 | U18: 1 | V18: 0 | W18: 1 | X18: 1 | Y18: 0 | Z18: 1 | AA18: 1 | AB18: 0 | AC18: 1 | AD18: 1 | AE18: 0 | AF18: 1 | AG18: 1 | AH18: =com.sun.star.sheet.addin.Analysis.getDec2Hex(AH22) -> 1B6DB6DB | AJ18: Channel | AK18: 10--19
B21: 0 | C21: 0 | D21: =IF(D17>0,2^D$1,0) -> 536870912 | E21: =IF(E17>0,2^E$1,0) -> 268435456 | F21: =IF(F17>0,2^F$1,0) -> 0 | G21: =IF(G17>0,2^G$1,0) -> 67108864 | H21: =IF(H17>0,2^H$1,0) -> 33554432 | I21: =IF(I17>0,2^I$1,0) -> 0 | J21: =IF(J17>0,2^J$1,0) -> 8388608 | K21: =IF(K17>0,2^K$1,0) -> 4194304 | ... AG21: =IF(AG17>0,2^AG$1,0) -> 0 | AH21: =SUM(B21:AG21) -> 920350134
B22: 0 | C22: 0 | D22: =IF(D18>0,2^D$1,0) -> 0 | E22: =IF(E18>0,2^E$1,0) -> 268435456 | F22: =IF(F18>0,2^F$1,0) -> 134217728 | G22: =IF(G18>0,2^G$1,0) -> 0 | H22: =IF(H18>0,2^H$1,0) -> 33554432 | I22: =IF(I18>0,2^I$1,0) -> 16777216 | J22: =IF(J18>0,2^J$1,0) -> 0 | K22: =IF(K18>0,2^K$1,0) -> 4194304 | ... AG22: =IF(AG18>0,2^AG$1,0) -> 1 | AH22: =SUM(B22:AG22) -> 460175067
B23: 0 | C23: 0 | D23: =IF(D19>0,2^D$1,0) -> 0 | E23: =IF(E19>0,2^E$1,0) -> 0 | F23: =IF(F19>0,2^F$1,0) -> 0 | G23: =IF(G19>0,2^G$1,0) -> 0 | H23: =IF(H19>0,2^H$1,0) -> 0 | I23: =IF(I19>0,2^I$1,0) -> 0 | J23: =IF(J19>0,2^J$1,0) -> 0 | K23: =IF(K19>0,2^K$1,0) -> 0 | ... AG23: =IF(AG19>0,2^AG$1,0) -> 0 | AH23: =SUM(B23:AG23) -> 0
B24: PORT B | R24: PORT A
A25: RI->HYSCR1 | B25: 0 | C25: 0 | D25: 0 | E25: 0 | F25: 0 | G25: 0 | H25: 0 | I25: 0 | J25: 0 | K25: 0 | L25: 0 | M25: 0 | N25: 0 | O25: 0 | P25: 0 | Q25: 1 | R25: 0 | S25: 0 | T25: 0 | U25: 0 | V25: 0 | W25: 0 | X25: 0 | Y25: 0 | Z25: 0 | AA25: 0 | AB25: 1 | AC25: 1 | AD25: 0 | AE25: 0 | AF25: 0 | AG25: 1 | AH25: =com.sun.star.sheet.addin.Analysis.getDec2Hex(AH26) -> 10031
B26: =IF(B25>0,2^B$1,0) -> 0 | C26: =IF(C25>0,2^C$1,0) -> 0 | D26: =IF(D25>0,2^D$1,0) -> 0 | E26: =IF(E25>0,2^E$1,0) -> 0 | F26: =IF(F25>0,2^F$1,0) -> 0 | G26: =IF(G25>0,2^G$1,0) -> 0 | H26: =IF(H25>0,2^H$1,0) -> 0 | I26: =IF(I25>0,2^I$1,0) -> 0 | ... AG26: =IF(AG25>0,2^AG$1,0) -> 1 | AH26: =SUM(B26:AG26) -> 65585
B27: PORT D | R27: PORT C
A28: RI->HYSCR2 | B28: 0 | C28: 0 | D28: 0 | E28: 0 | F28: 0 | G28: 0 | H28: 0 | I28: 0 | J28: 0 | K28: 0 | L28: 0 | M28: 0 | N28: 0 | O28: 0 | P28: 0 | Q28: 0 | R28: 0 | S28: 0 | T28: 0 | U28: 0 | V28: 0 | W28: 0 | X28: 0 | Y28: 0 | Z28: 0 | AA28: 0 | AB28: 0 | AC28: 0 | AD28: 0 | AE28: 0 | AF28: 0 | AG28: 0 | AH28: =com.sun.star.sheet.addin.Analysis.getDec2Hex(AH29) -> 0
B29: =IF(B28>0,2^B$1,0) -> 0 | C29: =IF(C28>0,2^C$1,0) -> 0 | D29: =IF(D28>0,2^D$1,0) -> 0 | E29: =IF(E28>0,2^E$1,0) -> 0 | F29: =IF(F28>0,2^F$1,0) -> 0 | G29: =IF(G28>0,2^G$1,0) -> 0 | H29: =IF(H28>0,2^H$1,0) -> 0 | I29: =IF(I28>0,2^I$1,0) -> 0 | ... AG29: =IF(AG28>0,2^AG$1,0) -> 0 | AH29: =SUM(B29:AG29) -> 0
B30: PORT F | R30: PORT E
A31: RI->HYSCR3 | B31: 0 | C31: 0 | D31: 0 | E31: 0 | F31: 0 | G31: 0 | H31: 0 | I31: 0 | J31: 0 | K31: 0 | L31: 0 | M31: 0 | N31: 0 | O31: 0 | P31: 0 | Q31: 0 | R31: 0 | S31: 0 | T31: 0 | U31: 0 | V31: 0 | W31: 1 | X31: 1 | Y31: 1 | Z31: 1 | AA31: 0 | AB31: 0 | AC31: 0 | AD31: 0 | AE31: 0 | AF31: 0 | AG31: 0 | AH31: =com.sun.star.sheet.addin.Analysis.getDec2Hex(AH32) -> 780
B32: =IF(B31>0,2^B$1,0) -> 0 | C32: =IF(C31>0,2^C$1,0) -> 0 | D32: =IF(D31>0,2^D$1,0) -> 0 | E32: =IF(E31>0,2^E$1,0) -> 0 | F32: =IF(F31>0,2^F$1,0) -> 0 | G32: =IF(G31>0,2^G$1,0) -> 0 | H32: =IF(H31>0,2^H$1,0) -> 0 | I32: =IF(I31>0,2^I$1,0) -> 0 | ... AG32: =IF(AG31>0,2^AG$1,0) -> 0 | AH32: =SUM(B32:AG32) -> 1920
A35: ADC->CR1 | B35: 0 | C35: 0 | D35: 0 | E35: 0 | F35: 0 | G35: 0 | H35: 0 | I35: 0 | J35: 0 | K35: 0 | L35: 0 | M35: 0 | N35: 0 | O35: 0 | P35: 0 | Q35: 0 | R35: 0 | S35: 0 | T35: 0 | U35: 0 | V35: 0 | W35: 0 | X35: 0 | Y35: 0 | Z35: 0 | AA35: 0 | AB35: 0 | AC35: 0 | AD35: 0 | AE35: 0 | AF35: 0 | AG35: 0 | AH35: =com.sun.star.sheet.addin.Analysis.getDec2Hex(AH36) -> 0
B36: =IF(B35>0,2^B$1,0) -> 0 | C36: =IF(C35>0,2^C$1,0) -> 0 | D36: =IF(D35>0,2^D$1,0) -> 0 | E36: =IF(E35>0,2^E$1,0) -> 0 | F36: =IF(F35>0,2^F$1,0) -> 0 | G36: =IF(G35>0,2^G$1,0) -> 0 | H36: =IF(H35>0,2^H$1,0) -> 0 | I36: =IF(I35>0,2^I$1,0) -> 0 | ... AG36: =IF(AG35>0,2^AG$1,0) -> 0 | AH36: =SUM(B36:AG36) -> 0
A39: ADC->CR2 | B39: 0 | C39: 0 | D39: 0 | E39: 0 | F39: 0 | G39: 0 | H39: 0 | I39: 0 | J39: 0 | K39: 0 | L39: 0 | M39: 0 | N39: 1 | O39: 1 | P39: 1 | Q39: 0 | R39: 0 | S39: 1 | T39: 1 | U39: 1 | V39: 0 | W39: 0 | X39: 0 | Y39: 1 | Z39: 0 | AA39: 0 | AB39: 0 | AC39: 0 | AD39: 1 | AE39: 0 | AF39: 0 | AG39: 1 | AH39: =com.sun.star.sheet.addin.Analysis.getDec2Hex(AH40) -> E7109 | AI39: Reset Cal Registers
B40: =IF(B39>0,2^B$1,0) -> 0 | C40: =IF(C39>0,2^C$1,0) -> 0 | D40: =IF(D39>0,2^D$1,0) -> 0 | E40: =IF(E39>0,2^E$1,0) -> 0 | F40: =IF(F39>0,2^F$1,0) -> 0 | G40: =IF(G39>0,2^G$1,0) -> 0 | H40: =IF(H39>0,2^H$1,0) -> 0 | I40: =IF(I39>0,2^I$1,0) -> 0 | ... AG40: =IF(AG39>0,2^AG$1,0) -> 1 | AH40: =SUM(B40:AG40) -> 946441
A42: ADC->CR2 | B42: 0 | C42: 0 | D42: 0 | E42: 0 | F42: 0 | G42: 0 | H42: 0 | I42: 0 | J42: 0 | K42: 0 | L42: 0 | M42: 1 | N42: 1 | O42: 1 | P42: 1 | Q42: 0 | R42: 0 | S42: 1 | T42: 1 | U42: 1 | V42: 0 | W42: 0 | X42: 0 | Y42: 1 | Z42: 0 | AA42: 0 | AB42: 0 | AC42: 0 | AD42: 0 | AE42: 1 | AF42: 0 | AG42: 1 | AH42: =com.sun.star.sheet.addin.Analysis.getDec2Hex(AH43) -> 1E7105 | AI42: Calibrate ADC
B43: =IF(B42>0,2^B$1,0) -> 0 | C43: =IF(C42>0,2^C$1,0) -> 0 | D43: =IF(D42>0,2^D$1,0) -> 0 | E43: =IF(E42>0,2^E$1,0) -> 0 | F43: =IF(F42>0,2^F$1,0) -> 0 | G43: =IF(G42>0,2^G$1,0) -> 0 | H43: =IF(H42>0,2^H$1,0) -> 0 | I43: =IF(I42>0,2^I$1,0) -> 0 | ... AG43: =IF(AG42>0,2^AG$1,0) -> 1 | AH43: =SUM(B43:AG43) -> 1995013 | AI43: To start set SWSTART(22)

Sheet Option Bytes
A3: BOR Level 4 | B3: 2.55-2.65V
A6: Below id the Option Byte Structure
A8: typedef struct | H8: Flash Register
A9: { | H9: typedef struct
A10: __IO uint32_t RDP; /*!< Read protection register, Address offset: 0x00 */ | H10: {
A11: __IO uint32_t USER; /*!< user register, Address offset: 0x04 */ | H11: __IO uint32_t ACR; /*!< Access control register, Address offset: 0x00 */
A12: __IO uint32_t WRP01; /*!< write protection register 0 1, Address offset: 0x08 */ | H12: __IO uint32_t PECR; /*!< Program/erase control register, Address offset: 0x04 */
A13: __IO uint32_t WRP23; /*!< write protection register 2 3, Address offset: 0x0C */ | H13: __IO uint32_t PDKEYR; /*!< Power down key register, Address offset: 0x08 */
A14: __IO uint32_t WRP45; /*!< write protection register 4 5, Address offset: 0x10 */ | H14: __IO uint32_t PEKEYR; /*!< Program/erase key register, Address offset: 0x0c */
A15: __IO uint32_t WRP67; /*!< write protection register 6 7, Address offset: 0x14 */ | H15: __IO uint32_t PRGKEYR; /*!< Program memory key register, Address offset: 0x10 */
A16: __IO uint32_t WRP89; /*!< write protection register 8 9, Address offset: 0x18 */ | H16: __IO uint32_t OPTKEYR; /*!< Option byte key register, Address offset: 0x14 */
A17: __IO uint32_t WRP1011; /*!< write protection register 10 11, Address offset: 0x1C */ | H17: __IO uint32_t SR; /*!< Status register, Address offset: 0x18 */
A18: } OB_TypeDef; | H18: __IO uint32_t OBR; /*!< Option byte register, Address offset: 0x1c */
H19: __IO uint32_t WRPR; /*!< Write protection register, Address offset: 0x20 */
H20: uint32_t RESERVED[23]; /*!< Reserved, 0x24 */
H21: __IO uint32_t WRPR1; /*!< Write protection register 1, Address offset: 0x28 */
H22: __IO uint32_t WRPR2; /*!< Write protection register 2, Address offset: 0x2C */
H23: } FLASH_TypeDef;

Sheet PWR & SYS
B1: 31 | C1: 30 | D1: 29 | E1: 28 | F1: 27 | G1: 26 | H1: 25 | I1: 24 | J1: 23 | K1: 22 | L1: 21 | M1: 20 | N1: 19 | O1: 18 | P1: 17 | Q1: 16 | R1: 15 | S1: 14 | T1: 13 | U1: 12 | V1: 11 | W1: 10 | X1: 9 | Y1: 8 | Z1: 7 | AA1: 6 | AB1: 5 | AC1: 4 | AD1: 3 | AE1: 2 | AF1: 1 | AG1: 0
A4: PWR->CR | B4: 0 | C4: 0 | D4: 0 | E4: 0 | F4: 0 | G4: 0 | H4: 0 | I4: 0 | J4: 0 | K4: 0 | L4: 0 | M4: 0 | N4: 0 | O4: 0 | P4: 0 | Q4: 0 | R4: 0 | S4: 0 | T4: 0 | U4: 0 | V4: 1 | W4: 1 | X4: 1 | Y4: 0 | Z4: 0 | AA4: 0 | AB4: 0 | AC4: 0 | AD4: 0 | AE4: 0 | AF4: 0 | AG4: 0 | AH4: =com.sun.star.sheet.addin.Analysis.getDec2Hex(AH5) -> E00
B5: =IF(B4>0,2^B$1,0) -> 0 | C5: =IF(C4>0,2^C$1,0) -> 0 | D5: =IF(D4>0,2^D$1,0) -> 0 | E5: =IF(E4>0,2^E$1,0) -> 0 | F5: =IF(F4>0,2^F$1,0) -> 0 | G5: =IF(G4>0,2^G$1,0) -> 0 | H5: =IF(H4>0,2^H$1,0) -> 0 | I5: =IF(I4>0,2^I$1,0) -> 0 | ... AG5: =IF(AG4>0,2^AG$1,0) -> 0 | AH5: =SUM(B5:AG5) -> 3584
A7: RCC->CFGR | B7: 1 | C7: 0 | D7: 0 | E7: 1 | F7: 1 | G7: 0 | H7: 0 | I7: 0 | J7: 0 | K7: 0 | L7: 0 | M7: 0 | N7: 0 | O7: 0 | P7: 0 | Q7: 0 | R7: 0 | S7: 0 | T7: 0 | U7: 0 | V7: 0 | W7: 0 | X7: 0 | Y7: 0 | Z7: 0 | AA7: 0 | AB7: 0 | AC7: 0 | AD7: 0 | AE7: 0 | AF7: 0 | AG7: 0 | AH7: =com.sun.star.sheet.addin.Analysis.getDec2Hex(AH8) -> 98000000 | AI7: OR this with Clock Generated code. This is sdadc CLCK. ADC clock is 6Mhz
B8: =IF(B7>0,2^B$1,0) -> 2147483648 | C8: =IF(C7>0,2^C$1,0) -> 0 | D8: =IF(D7>0,2^D$1,0) -> 0 | E8: =IF(E7>0,2^E$1,0) -> 268435456 | F8: =IF(F7>0,2^F$1,0) -> 134217728 | G8: =IF(G7>0,2^G$1,0) -> 0 | H8: =IF(H7>0,2^H$1,0) -> 0 | I8: =IF(I7>0,2^I$1,0) -> 0 | ... AG8: =IF(AG7>0,2^AG$1,0) -> 0 | AH8: =SUM(B8:AG8) -> 2550136832
A10: RCC->AHBENR | B10: 0 | C10: 0 | D10: 0 | E10: 0 | F10: 0 | G10: 0 | H10: 0 | I10: 0 | J10: 0 | K10: 1 | L10: 1 | M10: 1 | N10: 1 | O10: 1 | P10: 1 | Q10: 0 | R10: 0 | S10: 0 | T10: 0 | U10: 0 | V10: 0 | W10: 0 | X10: 0 | Y10: 0 | Z10: 0 | AA10: 0 | AB10: 0 | AC10: 0 | AD10: 0 | AE10: 0 | AF10: 0 | AG10: 1 | AH10: =com.sun.star.sheet.addin.Analysis.getDec2Hex(AH11) -> 7E0001
B11: =IF(B10>0,2^B$1,0) -> 0 | C11: =IF(C10>0,2^C$1,0) -> 0 | D11: =IF(D10>0,2^D$1,0) -> 0 | E11: =IF(E10>0,2^E$1,0) -> 0 | F11: =IF(F10>0,2^F$1,0) -> 0 | G11: =IF(G10>0,2^G$1,0) -> 0 | H11: =IF(H10>0,2^H$1,0) -> 0 | I11: =IF(I10>0,2^I$1,0) -> 0 | ... AG11: =IF(AG10>0,2^AG$1,0) -> 1 | AH11: =SUM(B11:AG11) -> 8257537
A13: RCC->APB2ENR | B13: 0 | C13: 0 | D13: 0 | E13: 0 | F13: 0 | G13: 1 | H13: 1 | I13: 1 | J13: 0 | K13: 0 | L13: 0 | M13: 0 | N13: 0 | O13: 0 | P13: 0 | Q13: 0 | R13: 0 | S13: 0 | T13: 0 | U13: 0 | V13: 0 | W13: 0 | X13: 1 | Y13: 0 | Z13: 0 | AA13: 0 | AB13: 0 | AC13: 0 | AD13: 0 | AE13: 0 | AF13: 0 | AG13: 1 | AH13: =com.sun.star.sheet.addin.Analysis.getDec2Hex(AH14) -> 7000201
B14: =IF(B13>0,2^B$1,0) -> 0 | C14: =IF(C13>0,2^C$1,0) -> 0 | D14: =IF(D13>0,2^D$1,0) -> 0 | E14: =IF(E13>0,2^E$1,0) -> 0 | F14: =IF(F13>0,2^F$1,0) -> 0 | G14: =IF(G13>0,2^G$1,0) -> 67108864 | H14: =IF(H13>0,2^H$1,0) -> 33554432 | I14: =IF(I13>0,2^I$1,0) -> 16777216 | ... AG14: =IF(AG13>0,2^AG$1,0) -> 1 | AH14: =SUM(B14:AG14) -> 117441025
A16: RCC->APB1ENR | B16: 0 | C16: 0 | D16: 0 | E16: 1 | F16: 0 | G16: 0 | H16: 0 | I16: 0 | J16: 0 | K16: 1 | L16: 0 | M16: 0 | N16: 0 | O16: 1 | P16: 0 | Q16: 0 | R16: 0 | S16: 0 | T16: 0 | U16: 0 | V16: 0 | W16: 0 | X16: 0 | Y16: 0 | Z16: 0 | AA16: 0 | AB16: 0 | AC16: 0 | AD16: 0 | AE16: 1 | AF16: 1 | AG16: 1 | AH16: =com.sun.star.sheet.addin.Analysis.getDec2Hex(AH17) -> 10440007
B17: =IF(B16>0,2^B$1,0) -> 0 | C17: =IF(C16>0,2^C$1,0) -> 0 | D17: =IF(D16>0,2^D$1,0) -> 0 | E17: =IF(E16>0,2^E$1,0) -> 268435456 | F17: =IF(F16>0,2^F$1,0) -> 0 | G17: =IF(G16>0,2^G$1,0) -> 0 | H17: =IF(H16>0,2^H$1,0) -> 0 | I17: =IF(I16>0,2^I$1,0) -> 0 | ... AG17: =IF(AG16>0,2^AG$1,0) -> 1 | AH17: =SUM(B17:AG17) -> 272891911
A19: RCC->BDCR | B19: 0 | C19: 0 | D19: 0 | E19: 0 | F19: 0 | G19: 0 | H19: 0 | I19: 0 | J19: 0 | K19: 0 | L19: 0 | M19: 0 | N19: 0 | O19: 0 | P19: 0 | Q19: 0 | R19: 0 | S19: 0 | T19: 0 | U19: 0 | V19: 0 | W19: 0 | X19: 0 | Y19: 0 | Z19: 0 | AA19: 0 | AB19: 0 | AC19: 0 | AD19: 0 | AE19: 0 | AF19: 0 | AG19: 0 | AH19: =com.sun.star.sheet.addin.Analysis.getDec2Hex(AH20) -> 0 | AI19: When RTC is required
B20: =IF(B19>0,2^B$1,0) -> 0 | C20: =IF(C19>0,2^C$1,0) -> 0 | D20: =IF(D19>0,2^D$1,0) -> 0 | E20: =IF(E19>0,2^E$1,0) -> 0 | F20: =IF(F19>0,2^F$1,0) -> 0 | G20: =IF(G19>0,2^G$1,0) -> 0 | H20: =IF(H19>0,2^H$1,0) -> 0 | I20: =IF(I19>0,2^I$1,0) -> 0 | ... AG20: =IF(AG19>0,2^AG$1,0) -> 0 | AH20: =SUM(B20:AG20) -> 0
A22: RCC->CFGR3 | B22: 0 | C22: 0 | D22: 0 | E22: 0 | F22: 0 | G22: 0 | H22: 0 | I22: 0 | J22: 0 | K22: 0 | L22: 0 | M22: 0 | N22: 0 | O22: 0 | P22: 0 | Q22: 0 | R22: 0 | S22: 0 | T22: 0 | U22: 0 | V22: 0 | W22: 0 | X22: 0 | Y22: 0 | Z22: 0 | AA22: 0 | AB22: 1 | AC22: 1 | AD22: 0 | AE22: 0 | AF22: 0 | AG22: 1 | AH22: =com.sun.star.sheet.addin.Analysis.getDec2Hex(AH23) -> 31 | AI22: Clock source for I2C, Usart Etc
B23: =IF(B22>0,2^B$1,0) -> 0 | C23: =IF(C22>0,2^C$1,0) -> 0 | D23: =IF(D22>0,2^D$1,0) -> 0 | E23: =IF(E22>0,2^E$1,0) -> 0 | F23: =IF(F22>0,2^F$1,0) -> 0 | G23: =IF(G22>0,2^G$1,0) -> 0 | H23: =IF(H22>0,2^H$1,0) -> 0 | I23: =IF(I22>0,2^I$1,0) -> 0 | ... AG23: =IF(AG22>0,2^AG$1,0) -> 1 | AH23: =SUM(B23:AG23) -> 49
A25: DMA->CCR | B25: 0 | C25: 0 | D25: 0 | E25: 0 | F25: 0 | G25: 0 | H25: 0 | I25: 0 | J25: 0 | K25: 0 | L25: 0 | M25: 0 | N25: 0 | O25: 0 | P25: 0 | Q25: 0 | R25: 0 | S25: 0 | T25: 0 | U25: 0 | V25: 0 | W25: 1 | X25: 0 | Y25: 1 | Z25: 1 | AA25: 0 | AB25: 1 | AC25: 0 | AD25: 0 | AE25: 0 | AF25: 0 | AG25: 1 | AH25: =com.sun.star.sheet.addin.Analysis.getDec2Hex(AH26) -> 5A1
B26: =IF(B25>0,2^B$1,0) -> 0 | C26: =IF(C25>0,2^C$1,0) -> 0 | D26: =IF(D25>0,2^D$1,0) -> 0 | E26: =IF(E25>0,2^E$1,0) -> 0 | F26: =IF(F25>0,2^F$1,0) -> 0 | G26: =IF(G25>0,2^G$1,0) -> 0 | H26: =IF(H25>0,2^H$1,0) -> 0 | I26: =IF(I25>0,2^I$1,0) -> 0 | ... AG26: =IF(AG25>0,2^AG$1,0) -> 1 | AH26: =SUM(B26:AG26) -> 1441
A28: DMA->CNDTR | B28: 0 | C28: 0 | D28: 0 | E28: 0 | F28: 0 | G28: 0 | H28: 0 | I28: 0 | J28: 0 | K28: 0 | L28: 0 | M28: 0 | N28: 0 | O28: 0 | P28: 0 | Q28: 0 | R28: 0 | S28: 0 | T28: 0 | U28: 0 | V28: 0 | W28: 0 | X28: 0 | Y28: 0 | Z28: 0 | AA28: 0 | AB28: 0 | AC28: 0 | AD28: 0 | AE28: 0 | AF28: 0 | AG28: 0 | AH28: =com.sun.star.sheet.addin.Analysis.getDec2Hex(AH29) -> 0 | AI28: No of data transfer
B29: =IF(B28>0,2^B$1,0) -> 0 | C29: =IF(C28>0,2^C$1,0) -> 0 | D29: =IF(D28>0,2^D$1,0) -> 0 | E29: =IF(E28>0,2^E$1,0) -> 0 | F29: =IF(F28>0,2^F$1,0) -> 0 | G29: =IF(G28>0,2^G$1,0) -> 0 | H29: =IF(H28>0,2^H$1,0) -> 0 | I29: =IF(I28>0,2^I$1,0) -> 0 | ... AG29: =IF(AG28>0,2^AG$1,0) -> 0 | AH29: =SUM(B29:AG29) -> 0
A31: DMA->CPAR | B31: 0 | C31: 0 | D31: 0 | E31: 0 | F31: 0 | G31: 0 | H31: 0 | I31: 0 | J31: 0 | K31: 0 | L31: 0 | M31: 0 | N31: 0 | O31: 0 | P31: 0 | Q31: 0 | R31: 0 | S31: 0 | T31: 0 | U31: 0 | V31: 0 | W31: 0 | X31: 0 | Y31: 0 | Z31: 0 | AA31: 0 | AB31: 0 | AC31: 0 | AD31: 0 | AE31: 0 | AF31: 0 | AG31: 0 | AH31: =com.sun.star.sheet.addin.Analysis.getDec2Hex(AH32) -> 0 | AI31: Add of ADC register
B32: =IF(B31>0,2^B$1,0) -> 0 | C32: =IF(C31>0,2^C$1,0) -> 0 | D32: =IF(D31>0,2^D$1,0) -> 0 | E32: =IF(E31>0,2^E$1,0) -> 0 | F32: =IF(F31>0,2^F$1,0) -> 0 | G32: =IF(G31>0,2^G$1,0) -> 0 | H32: =IF(H31>0,2^H$1,0) -> 0 | I32: =IF(I31>0,2^I$1,0) -> 0 | ... AG32: =IF(AG31>0,2^AG$1,0) -> 0 | AH32: =SUM(B32:AG32) -> 0
A34: DMA->CMAR | B34: 0 | C34: 0 | D34: 0 | E34: 0 | F34: 0 | G34: 0 | H34: 0 | I34: 0 | J34: 0 | K34: 0 | L34: 0 | M34: 0 | N34: 0 | O34: 0 | P34: 0 | Q34: 0 | R34: 0 | S34: 0 | T34: 0 | U34: 0 | V34: 0 | W34: 0 | X34: 0 | Y34: 0 | Z34: 0 | AA34: 0 | AB34: 0 | AC34: 0 | AD34: 0 | AE34: 0 | AF34: 0 | AG34: 0 | AH34: =com.sun.star.sheet.addin.Analysis.getDec2Hex(AH35) -> 0 | AI34: Add of memory
B35: =IF(B34>0,2^B$1,0) -> 0 | C35: =IF(C34>0,2^C$1,0) -> 0 | D35: =IF(D34>0,2^D$1,0) -> 0 | E35: =IF(E34>0,2^E$1,0) -> 0 | F35: =IF(F34>0,2^F$1,0) -> 0 | G35: =IF(G34>0,2^G$1,0) -> 0 | H35: =IF(H34>0,2^H$1,0) -> 0 | I35: =IF(I34>0,2^I$1,0) -> 0 | ... AG35: =IF(AG34>0,2^AG$1,0) -> 0 | AH35: =SUM(B35:AG35) -> 0
A37: RCC->APB2RSTR | B37: 0 | C37: 0 | D37: 0 | E37: 0 | F37: 0 | G37: 1 | H37: 1 | I37: 1 | J37: 0 | K37: 0 | L37: 0 | M37: 0 | N37: 1 | O37: 1 | P37: 1 | Q37: 1 | R37: 0 | S37: 1 | T37: 0 | U37: 1 | V37: 0 | W37: 0 | X37: 1 | Y37: 0 | Z37: 0 | AA37: 0 | AB37: 0 | AC37: 0 | AD37: 0 | AE37: 0 | AF37: 0 | AG37: 1 | AH37: =com.sun.star.sheet.addin.Analysis.getDec2Hex(AH38) -> 70F5201
B38: =IF(B37>0,2^B$1,0) -> 0 | C38: =IF(C37>0,2^C$1,0) -> 0 | D38: =IF(D37>0,2^D$1,0) -> 0 | E38: =IF(E37>0,2^E$1,0) -> 0 | F38: =IF(F37>0,2^F$1,0) -> 0 | G38: =IF(G37>0,2^G$1,0) -> 67108864 | H38: =IF(H37>0,2^H$1,0) -> 33554432 | I38: =IF(I37>0,2^I$1,0) -> 16777216 | ... AG38: =IF(AG37>0,2^AG$1,0) -> 1 | AH38: =SUM(B38:AG38) -> 118444545
A40: RCC->APB1RSTR | B40: 0 | C40: 1 | D40: 1 | E40: 1 | F40: 0 | G40: 1 | H40: 1 | I40: 0 | J40: 1 | K40: 1 | L40: 1 | M40: 0 | N40: 0 | O40: 1 | P40: 1 | Q40: 0 | R40: 1 | S40: 1 | T40: 0 | U40: 0 | V40: 1 | W40: 0 | X40: 1 | Y40: 1 | Z40: 1 | AA40: 1 | AB40: 1 | AC40: 1 | AD40: 1 | AE40: 1 | AF40: 1 | AG40: 1 | AH40: =com.sun.star.sheet.addin.Analysis.getDec2Hex(AH41) -> 76E6CBFF
B41: =IF(B40>0,2^B$1,0) -> 0 | C41: =IF(C40>0,2^C$1,0) -> 1073741824 | D41: =IF(D40>0,2^D$1,0) -> 536870912 | E41: =IF(E40>0,2^E$1,0) -> 268435456 | F41: =IF(F40>0,2^F$1,0) -> 0 | G41: =IF(G40>0,2^G$1,0) -> 67108864 | H41: =IF(H40>0,2^H$1,0) -> 33554432 | I41: =IF(I40>0,2^I$1,0) -> 0 | ... AG41: =IF(AG40>0,2^AG$1,0) -> 1 | AH41: =SUM(B41:AG41) -> 1994836991
A48: SYSCFG | B48: At present all at 00 but may be done in future to enable external interrupts etc

Sheet SDADC
B1: 31 | C1: 30 | D1: 29 | E1: 28 | F1: 27 | G1: 26 | H1: 25 | I1: 24 | J1: 23 | K1: 22 | L1: 21 | M1: 20 | N1: 19 | O1: 18 | P1: 17 | Q1: 16 | R1: 15 | S1: 14 | T1: 13 | U1: 12 | V1: 11 | W1: 10 | X1: 9 | Y1: 8 | Z1: 7 | AA1: 6 | AB1: 5 | AC1: 4 | AD1: 3 | AE1: 2 | AF1: 1 | AG1: 0
A4: SDADC1->CR1 | B4: 0 | C4: 0 | D4: 0 | E4: 0 | F4: 0 | G4: 0 | H4: 0 | I4: 0 | J4: 0 | K4: 0 | L4: 0 | M4: 0 | N4: 0 | O4: 0 | P4: 0 | Q4: 0 | R4: 0 | S4: 1 | T4: 0 | U4: 0 | V4: 0 | W4: 0 | X4: 0 | Y4: 1 | Z4: 0 | AA4: 0 | AB4: 0 | AC4: 0 | AD4: 0 | AE4: 0 | AF4: 0 | AG4: 0 | AH4: =com.sun.star.sheet.addin.Analysis.getDec2Hex(AH5) -> 4100
B5: =IF(B4>0,2^B$1,0) -> 0 | C5: =IF(C4>0,2^C$1,0) -> 0 | D5: =IF(D4>0,2^D$1,0) -> 0 | E5: =IF(E4>0,2^E$1,0) -> 0 | F5: =IF(F4>0,2^F$1,0) -> 0 | G5: =IF(G4>0,2^G$1,0) -> 0 | H5: =IF(H4>0,2^H$1,0) -> 0 | I5: =IF(I4>0,2^I$1,0) -> 0 | ... AG5: =IF(AG4>0,2^AG$1,0) -> 0 | AH5: =SUM(B5:AG5) -> 16640
A7: SDADC->CR2 | B7: 0 | C7: 0 | D7: 0 | E7: 0 | F7: 0 | G7: 0 | H7: 0 | I7: 0 | J7: 0 | K7: 0 | L7: 0 | M7: 0 | N7: 0 | O7: 0 | P7: 0 | Q7: 0 | R7: 0 | S7: 0 | T7: 0 | U7: 0 | V7: 0 | W7: 0 | X7: 0 | Y7: 0 | Z7: 0 | AA7: 0 | AB7: 0 | AC7: 0 | AD7: 0 | AE7: 0 | AF7: 0 | AG7: 1 | AH7: =com.sun.star.sheet.addin.Analysis.getDec2Hex(AH8) -> 1
B8: =IF(B7>0,2^B$1,0) -> 0 | C8: =IF(C7>0,2^C$1,0) -> 0 | D8: =IF(D7>0,2^D$1,0) -> 0 | E8: =IF(E7>0,2^E$1,0) -> 0 | F8: =IF(F7>0,2^F$1,0) -> 0 | G8: =IF(G7>0,2^G$1,0) -> 0 | H8: =IF(H7>0,2^H$1,0) -> 0 | I8: =IF(I7>0,2^I$1,0) -> 0 | ... AG8: =IF(AG7>0,2^AG$1,0) -> 1 | AH8: =SUM(B8:AG8) -> 1
A10: SDADC1->JCHGR | B10: 0 | C10: 0 | D10: 0 | E10: 0 | F10: 0 | G10: 0 | H10: 0 | I10: 0 | J10: 0 | K10: 0 | L10: 0 | M10: 0 | N10: 0 | O10: 0 | P10: 0 | Q10: 0 | R10: 0 | S10: 0 | T10: 0 | U10: 0 | V10: 0 | W10: 0 | X10: 0 | Y10: 0 | Z10: 0 | AA10: 1 | AB10: 0 | AC10: 0 | AD10: 0 | AE10: 0 | AF10: 0 | AG10: 0 | AH10: =com.sun.star.sheet.addin.Analysis.getDec2Hex(AH11) -> 40
B11: =IF(B10>0,2^B$1,0) -> 0 | C11: =IF(C10>0,2^C$1,0) -> 0 | D11: =IF(D10>0,2^D$1,0) -> 0 | E11: =IF(E10>0,2^E$1,0) -> 0 | F11: =IF(F10>0,2^F$1,0) -> 0 | G11: =IF(G10>0,2^G$1,0) -> 0 | H11: =IF(H10>0,2^H$1,0) -> 0 | I11: =IF(I10>0,2^I$1,0) -> 0 | ... AG11: =IF(AG10>0,2^AG$1,0) -> 0 | AH11: =SUM(B11:AG11) -> 64
A13: SDADC2->JCHGR | B13: 0 | C13: 0 | D13: 0 | E13: 0 | F13: 0 | G13: 0 | H13: 0 | I13: 0 | J13: 0 | K13: 0 | L13: 0 | M13: 0 | N13: 0 | O13: 0 | P13: 0 | Q13: 0 | R13: 0 | S13: 0 | T13: 0 | U13: 0 | V13: 0 | W13: 0 | X13: 0 | Y13: 1 | Z13: 0 | AA13: 0 | AB13: 0 | AC13: 0 | AD13: 0 | AE13: 0 | AF13: 0 | AG13: 0 | AH13: =com.sun.star.sheet.addin.Analysis.getDec2Hex(AH14) -> 100
B14: =IF(B13>0,2^B$1,0) -> 0 | C14: =IF(C13>0,2^C$1,0) -> 0 | D14: =IF(D13>0,2^D$1,0) -> 0 | E14: =IF(E13>0,2^E$1,0) -> 0 | F14: =IF(F13>0,2^F$1,0) -> 0 | G14: =IF(G13>0,2^G$1,0) -> 0 | H14: =IF(H13>0,2^H$1,0) -> 0 | I14: =IF(I13>0,2^I$1,0) -> 0 | ... AG14: =IF(AG13>0,2^AG$1,0) -> 0 | AH14: =SUM(B14:AG14) -> 256
A16: SDADC3->JCHGR | B16: 0 | C16: 0 | D16: 0 | E16: 0 | F16: 0 | G16: 0 | H16: 0 | I16: 0 | J16: 0 | K16: 0 | L16: 0 | M16: 0 | N16: 0 | O16: 0 | P16: 0 | Q16: 0 | R16: 0 | S16: 0 | T16: 0 | U16: 0 | V16: 0 | W16: 0 | X16: 0 | Y16: 1 | Z16: 0 | AA16: 0 | AB16: 0 | AC16: 0 | AD16: 0 | AE16: 0 | AF16: 0 | AG16: 0 | AH16: =com.sun.star.sheet.addin.Analysis.getDec2Hex(AH17) -> 100
B17: =IF(B16>0,2^B$1,0) -> 0 | C17: =IF(C16>0,2^C$1,0) -> 0 | D17: =IF(D16>0,2^D$1,0) -> 0 | E17: =IF(E16>0,2^E$1,0) -> 0 | F17: =IF(F16>0,2^F$1,0) -> 0 | G17: =IF(G16>0,2^G$1,0) -> 0 | H17: =IF(H16>0,2^H$1,0) -> 0 | I17: =IF(I16>0,2^I$1,0) -> 0 | ... AG17: =IF(AG16>0,2^AG$1,0) -> 0 | AH17: =SUM(B17:AG17) -> 256
A19: SDADC1/2/3->CONF0R | B19: 0 | C19: 0 | D19: 0 | E19: 0 | F19: 0 | G19: 0 | H19: 0 | I19: 0 | J19: 0 | K19: 0 | L19: 0 | M19: 1 | N19: 0 | O19: 0 | P19: 0 | Q19: 0 | R19: 0 | S19: 0 | T19: 0 | U19: 0 | V19: 0 | W19: 0 | X19: 0 | Y19: 0 | Z19: 0 | AA19: 0 | AB19: 0 | AC19: 0 | AD19: 0 | AE19: 0 | AF19: 0 | AG19: 0 | AH19: =com.sun.star.sheet.addin.Analysis.getDec2Hex(AH20) -> 100000
B20: =IF(B19>0,2^B$1,0) -> 0 | C20: =IF(C19>0,2^C$1,0) -> 0 | D20: =IF(D19>0,2^D$1,0) -> 0 | E20: =IF(E19>0,2^E$1,0) -> 0 | F20: =IF(F19>0,2^F$1,0) -> 0 | G20: =IF(G19>0,2^G$1,0) -> 0 | H20: =IF(H19>0,2^H$1,0) -> 0 | I20: =IF(I19>0,2^I$1,0) -> 0 | ... AG20: =IF(AG19>0,2^AG$1,0) -> 0 | AH20: =SUM(B20:AG20) -> 1048576
B22: 0 | C22: 0 | D22: 0 | E22: 0 | F22: 0 | G22: 0 | H22: 0 | I22: 0 | J22: 0 | K22: 0 | L22: 0 | M22: 0 | N22: 0 | O22: 0 | P22: 0 | Q22: 0 | R22: 0 | S22: 0 | T22: 0 | U22: 0 | V22: 0 | W22: 0 | X22: 0 | Y22: 0 | Z22: 0 | AA22: 0 | AB22: 0 | AC22: 0 | AD22: 0 | AE22: 0 | AF22: 0 | AG22: 0 | AH22: =com.sun.star.sheet.addin.Analysis.getDec2Hex(AH23) -> 0
B23: =IF(B22>0,2^B$1,0) -> 0 | C23: =IF(C22>0,2^C$1,0) -> 0 | D23: =IF(D22>0,2^D$1,0) -> 0 | E23: =IF(E22>0,2^E$1,0) -> 0 | F23: =IF(F22>0,2^F$1,0) -> 0 | G23: =IF(G22>0,2^G$1,0) -> 0 | H23: =IF(H22>0,2^H$1,0) -> 0 | I23: =IF(I22>0,2^I$1,0) -> 0 | ... AG23: =IF(AG22>0,2^AG$1,0) -> 0 | AH23: =SUM(B23:AG23) -> 0
B25: 0 | C25: 0 | D25: 0 | E25: 0 | F25: 0 | G25: 0 | H25: 0 | I25: 0 | J25: 0 | K25: 0 | L25: 0 | M25: 0 | N25: 0 | O25: 0 | P25: 0 | Q25: 0 | R25: 0 | S25: 0 | T25: 0 | U25: 0 | V25: 0 | W25: 0 | X25: 0 | Y25: 0 | Z25: 0 | AA25: 0 | AB25: 0 | AC25: 0 | AD25: 0 | AE25: 0 | AF25: 0 | AG25: 0 | AH25: =com.sun.star.sheet.addin.Analysis.getDec2Hex(AH26) -> 0
B26: =IF(B25>0,2^B$1,0) -> 0 | C26: =IF(C25>0,2^C$1,0) -> 0 | D26: =IF(D25>0,2^D$1,0) -> 0 | E26: =IF(E25>0,2^E$1,0) -> 0 | F26: =IF(F25>0,2^F$1,0) -> 0 | G26: =IF(G25>0,2^G$1,0) -> 0 | H26: =IF(H25>0,2^H$1,0) -> 0 | I26: =IF(I25>0,2^I$1,0) -> 0 | ... AG26: =IF(AG25>0,2^AG$1,0) -> 0 | AH26: =SUM(B26:AG26) -> 0
B28: 0 | C28: 0 | D28: 0 | E28: 0 | F28: 0 | G28: 0 | H28: 0 | I28: 0 | J28: 0 | K28: 0 | L28: 0 | M28: 0 | N28: 0 | O28: 0 | P28: 0 | Q28: 0 | R28: 0 | S28: 0 | T28: 0 | U28: 0 | V28: 0 | W28: 0 | X28: 0 | Y28: 0 | Z28: 0 | AA28: 0 | AB28: 0 | AC28: 0 | AD28: 0 | AE28: 0 | AF28: 0 | AG28: 0 | AH28: =com.sun.star.sheet.addin.Analysis.getDec2Hex(AH29) -> 0
B29: =IF(B28>0,2^B$1,0) -> 0 | C29: =IF(C28>0,2^C$1,0) -> 0 | D29: =IF(D28>0,2^D$1,0) -> 0 | E29: =IF(E28>0,2^E$1,0) -> 0 | F29: =IF(F28>0,2^F$1,0) -> 0 | G29: =IF(G28>0,2^G$1,0) -> 0 | H29: =IF(H28>0,2^H$1,0) -> 0 | I29: =IF(I28>0,2^I$1,0) -> 0 | ... AG29: =IF(AG28>0,2^AG$1,0) -> 0 | AH29: =SUM(B29:AG29) -> 0

Sheet Sheet1
B1: 31 | C1: 30 | D1: 29 | E1: 28 | F1: 27 | G1: 26 | H1: 25 | I1: 24 | J1: 23 | K1: 22 | L1: 21 | M1: 20 | N1: 19 | O1: 18 | P1: 17 | Q1: 16 | R1: 15 | S1: 14 | T1: 13 | U1: 12 | V1: 11 | W1: 10 | X1: 9 | Y1: 8 | Z1: 7 | AA1: 6 | AB1: 5 | AC1: 4 | AD1: 3 | AE1: 2 | AF1: 1 | AG1: 0
A3: TIM2->CR1 | B3: 0 | C3: 0 | D3: 0 | E3: 0 | F3: 0 | G3: 0 | H3: 0 | I3: 0 | J3: 0 | K3: 0 | L3: 0 | M3: 0 | N3: 0 | O3: 0 | P3: 0 | Q3: 0 | R3: 0 | S3: 0 | T3: 0 | U3: 0 | V3: 0 | W3: 0 | X3: 0 | Y3: 0 | Z3: 1 | AA3: 0 | AB3: 0 | AC3: 0 | AD3: 0 | AE3: 1 | AF3: 0 | AG3: 0 | AH3: =com.sun.star.sheet.addin.Analysis.getDec2Hex(AH4) -> 84
B4: =IF(B3>0,2^'PWR & SYS'!B$1,0) -> 0 | C4: =IF(C3>0,2^'PWR & SYS'!C$1,0) -> 0 | D4: =IF(D3>0,2^'PWR & SYS'!D$1,0) -> 0 | E4: =IF(E3>0,2^'PWR & SYS'!E$1,0) -> 0 | F4: =IF(F3>0,2^'PWR & SYS'!F$1,0) -> 0 | G4: =IF(G3>0,2^'PWR & SYS'!G$1,0) -> 0 | H4: =IF(H3>0,2^'PWR & SYS'!H$1,0) -> 0 | I4: =IF(I3>0,2^'PWR & SYS'!I$1,0) -> 0 | ... AG4: =IF(AG3>0,2^'PWR & SYS'!AG$1,0) -> 0 | AH4: =SUM(B4:AG4) -> 132
A6: I2C->CR1 | B6: 0 | C6: 0 | D6: 0 | E6: 0 | F6: 0 | G6: 0 | H6: 0 | I6: 0 | J6: 0 | K6: 0 | L6: 0 | M6: 0 | N6: 0 | O6: 0 | P6: 0 | Q6: 0 | R6: 0 | S6: 0 | T6: 0 | U6: 0 | V6: 0 | W6: 0 | X6: 0 | Y6: 0 | Z6: 0 | AA6: 0 | AB6: 0 | AC6: 0 | AD6: 0 | AE6: 0 | AF6: 0 | AG6: 1 | AH6: =com.sun.star.sheet.addin.Analysis.getDec2Hex(AH7) -> 1
B7: =IF(B6>0,2^'PWR & SYS'!B$1,0) -> 0 | C7: =IF(C6>0,2^'PWR & SYS'!C$1,0) -> 0 | D7: =IF(D6>0,2^'PWR & SYS'!D$1,0) -> 0 | E7: =IF(E6>0,2^'PWR & SYS'!E$1,0) -> 0 | F7: =IF(F6>0,2^'PWR & SYS'!F$1,0) -> 0 | G7: =IF(G6>0,2^'PWR & SYS'!G$1,0) -> 0 | H7: =IF(H6>0,2^'PWR & SYS'!H$1,0) -> 0 | I7: =IF(I6>0,2^'PWR & SYS'!I$1,0) -> 0 | ... AG7: =IF(AG6>0,2^'PWR & SYS'!AG$1,0) -> 1 | AH7: =SUM(B7:AG7) -> 1
A9: PWR->CR | B9: 0 | C9: 0 | D9: 0 | E9: 0 | F9: 0 | G9: 0 | H9: 0 | I9: 0 | J9: 0 | K9: 0 | L9: 0 | M9: 0 | N9: 0 | O9: 0 | P9: 0 | Q9: 0 | R9: 0 | S9: 0 | T9: 0 | U9: 0 | V9: 0 | W9: 0 | X9: 0 | Y9: 0 | Z9: 0 | AA9: 0 | AB9: 0 | AC9: 0 | AD9: 0 | AE9: 0 | AF9: 0 | AG9: 0 | AH9: =com.sun.star.sheet.addin.Analysis.getDec2Hex(AH10) -> 0
B10: =IF(B9>0,2^'PWR & SYS'!B$1,0) -> 0 | C10: =IF(C9>0,2^'PWR & SYS'!C$1,0) -> 0 | D10: =IF(D9>0,2^'PWR & SYS'!D$1,0) -> 0 | E10: =IF(E9>0,2^'PWR & SYS'!E$1,0) -> 0 | F10: =IF(F9>0,2^'PWR & SYS'!F$1,0) -> 0 | G10: =IF(G9>0,2^'PWR & SYS'!G$1,0) -> 0 | H10: =IF(H9>0,2^'PWR & SYS'!H$1,0) -> 0 | I10: =IF(I9>0,2^'PWR & SYS'!I$1,0) -> 0 | ... AG10: =IF(AG9>0,2^'PWR & SYS'!AG$1,0) -> 0 | AH10: =SUM(B10:AG10) -> 0
A12: PWR->CR | B12: 0 | C12: 0 | D12: 0 | E12: 0 | F12: 0 | G12: 0 | H12: 0 | I12: 0 | J12: 0 | K12: 0 | L12: 0 | M12: 0 | N12: 0 | O12: 0 | P12: 0 | Q12: 0 | R12: 0 | S12: 0 | T12: 0 | U12: 0 | V12: 0 | W12: 0 | X12: 0 | Y12: 0 | Z12: 0 | AA12: 0 | AB12: 0 | AC12: 0 | AD12: 0 | AE12: 0 | AF12: 0 | AG12: 0 | AH12: =com.sun.star.sheet.addin.Analysis.getDec2Hex(AH13) -> 0
B13: =IF(B12>0,2^'PWR & SYS'!B$1,0) -> 0 | C13: =IF(C12>0,2^'PWR & SYS'!C$1,0) -> 0 | D13: =IF(D12>0,2^'PWR & SYS'!D$1,0) -> 0 | E13: =IF(E12>0,2^'PWR & SYS'!E$1,0) -> 0 | F13: =IF(F12>0,2^'PWR & SYS'!F$1,0) -> 0 | G13: =IF(G12>0,2^'PWR & SYS'!G$1,0) -> 0 | H13: =IF(H12>0,2^'PWR & SYS'!H$1,0) -> 0 | I13: =IF(I12>0,2^'PWR & SYS'!I$1,0) -> 0 | ... AG13: =IF(AG12>0,2^'PWR & SYS'!AG$1,0) -> 0 | AH13: =SUM(B13:AG13) -> 0
